Assay endpoint with aeid=2705 failed: cannot set a frame with no defined index and a scalar
Traceback (most recent call last):
  File "/home/bossh/pytcpl/src/pipeline/pipeline_main.py", line 43, in pipeline
    df = process(df, config, logger)
  File "/home/bossh/pytcpl/src/pipeline/pipeline_core.py", line 189, in process
    df_no_fit.loc[:, 'fit_params'] = None
  File "/usr/local/lib/python3.9/dist-packages/pandas/core/indexing.py", line 849, in __setitem__
    iloc._setitem_with_indexer(indexer, value, self.name)
  File "/usr/local/lib/python3.9/dist-packages/pandas/core/indexing.py", line 1751, in _setitem_with_indexer
    raise ValueError(
ValueError: cannot set a frame with no defined index and a scalar

Assay endpoint with aeid=2681 failed: cannot set a frame with no defined index and a scalar
Traceback (most recent call last):
  File "/home/bossh/pytcpl/src/pipeline/pipeline_main.py", line 43, in pipeline
    df = process(df, config, logger)
  File "/home/bossh/pytcpl/src/pipeline/pipeline_core.py", line 189, in process
    df_no_fit.loc[:, 'fit_params'] = None
  File "/usr/local/lib/python3.9/dist-packages/pandas/core/indexing.py", line 849, in __setitem__
    iloc._setitem_with_indexer(indexer, value, self.name)
  File "/usr/local/lib/python3.9/dist-packages/pandas/core/indexing.py", line 1751, in _setitem_with_indexer
    raise ValueError(
ValueError: cannot set a frame with no defined index and a scalar

Assay endpoint with aeid=2692 failed: cannot set a frame with no defined index and a scalar
Traceback (most recent call last):
  File "/home/bossh/pytcpl/src/pipeline/pipeline_main.py", line 43, in pipeline
    df = process(df, config, logger)
  File "/home/bossh/pytcpl/src/pipeline/pipeline_core.py", line 189, in process
    df_no_fit.loc[:, 'fit_params'] = None
  File "/usr/local/lib/python3.9/dist-packages/pandas/core/indexing.py", line 849, in __setitem__
    iloc._setitem_with_indexer(indexer, value, self.name)
  File "/usr/local/lib/python3.9/dist-packages/pandas/core/indexing.py", line 1751, in _setitem_with_indexer
    raise ValueError(
ValueError: cannot set a frame with no defined index and a scalar

Assay endpoint with aeid=2691 failed: cannot set a frame with no defined index and a scalar
Traceback (most recent call last):
  File "/home/bossh/pytcpl/src/pipeline/pipeline_main.py", line 43, in pipeline
    df = process(df, config, logger)
  File "/home/bossh/pytcpl/src/pipeline/pipeline_core.py", line 189, in process
    df_no_fit.loc[:, 'fit_params'] = None
  File "/usr/local/lib/python3.9/dist-packages/pandas/core/indexing.py", line 849, in __setitem__
    iloc._setitem_with_indexer(indexer, value, self.name)
  File "/usr/local/lib/python3.9/dist-packages/pandas/core/indexing.py", line 1751, in _setitem_with_indexer
    raise ValueError(
ValueError: cannot set a frame with no defined index and a scalar

Assay endpoint with aeid=2695 failed: cannot set a frame with no defined index and a scalar
Traceback (most recent call last):
  File "/home/bossh/pytcpl/src/pipeline/pipeline_main.py", line 43, in pipeline
    df = process(df, config, logger)
  File "/home/bossh/pytcpl/src/pipeline/pipeline_core.py", line 189, in process
    df_no_fit.loc[:, 'fit_params'] = None
  File "/usr/local/lib/python3.9/dist-packages/pandas/core/indexing.py", line 849, in __setitem__
    iloc._setitem_with_indexer(indexer, value, self.name)
  File "/usr/local/lib/python3.9/dist-packages/pandas/core/indexing.py", line 1751, in _setitem_with_indexer
    raise ValueError(
ValueError: cannot set a frame with no defined index and a scalar

Assay endpoint with aeid=2600 failed: cannot set a frame with no defined index and a scalar
Traceback (most recent call last):
  File "/home/bossh/pytcpl/src/pipeline/pipeline_main.py", line 43, in pipeline
    df = process(df, config, logger)
  File "/home/bossh/pytcpl/src/pipeline/pipeline_core.py", line 189, in process
    df_no_fit.loc[:, 'fit_params'] = None
  File "/usr/local/lib/python3.9/dist-packages/pandas/core/indexing.py", line 849, in __setitem__
    iloc._setitem_with_indexer(indexer, value, self.name)
  File "/usr/local/lib/python3.9/dist-packages/pandas/core/indexing.py", line 1751, in _setitem_with_indexer
    raise ValueError(
ValueError: cannot set a frame with no defined index and a scalar

Assay endpoint with aeid=2581 failed: cannot set a frame with no defined index and a scalar
Traceback (most recent call last):
  File "/home/bossh/pytcpl/src/pipeline/pipeline_main.py", line 43, in pipeline
    df = process(df, config, logger)
  File "/home/bossh/pytcpl/src/pipeline/pipeline_core.py", line 189, in process
    df_no_fit.loc[:, 'fit_params'] = None
  File "/usr/local/lib/python3.9/dist-packages/pandas/core/indexing.py", line 849, in __setitem__
    iloc._setitem_with_indexer(indexer, value, self.name)
  File "/usr/local/lib/python3.9/dist-packages/pandas/core/indexing.py", line 1751, in _setitem_with_indexer
    raise ValueError(
ValueError: cannot set a frame with no defined index and a scalar

Assay endpoint with aeid=2554 failed: cannot set a frame with no defined index and a scalar
Traceback (most recent call last):
  File "/home/bossh/pytcpl/src/pipeline/pipeline_main.py", line 43, in pipeline
    df = process(df, config, logger)
  File "/home/bossh/pytcpl/src/pipeline/pipeline_core.py", line 189, in process
    df_no_fit.loc[:, 'fit_params'] = None
  File "/usr/local/lib/python3.9/dist-packages/pandas/core/indexing.py", line 849, in __setitem__
    iloc._setitem_with_indexer(indexer, value, self.name)
  File "/usr/local/lib/python3.9/dist-packages/pandas/core/indexing.py", line 1751, in _setitem_with_indexer
    raise ValueError(
ValueError: cannot set a frame with no defined index and a scalar

Assay endpoint with aeid=2558 failed: cannot set a frame with no defined index and a scalar
Traceback (most recent call last):
  File "/home/bossh/pytcpl/src/pipeline/pipeline_main.py", line 43, in pipeline
    df = process(df, config, logger)
  File "/home/bossh/pytcpl/src/pipeline/pipeline_core.py", line 189, in process
    df_no_fit.loc[:, 'fit_params'] = None
  File "/usr/local/lib/python3.9/dist-packages/pandas/core/indexing.py", line 849, in __setitem__
    iloc._setitem_with_indexer(indexer, value, self.name)
  File "/usr/local/lib/python3.9/dist-packages/pandas/core/indexing.py", line 1751, in _setitem_with_indexer
    raise ValueError(
ValueError: cannot set a frame with no defined index and a scalar

Assay endpoint with aeid=2666 failed: cannot set a frame with no defined index and a scalar
Traceback (most recent call last):
  File "/home/bossh/pytcpl/src/pipeline/pipeline_main.py", line 43, in pipeline
    df = process(df, config, logger)
  File "/home/bossh/pytcpl/src/pipeline/pipeline_core.py", line 189, in process
    df_no_fit.loc[:, 'fit_params'] = None
  File "/usr/local/lib/python3.9/dist-packages/pandas/core/indexing.py", line 849, in __setitem__
    iloc._setitem_with_indexer(indexer, value, self.name)
  File "/usr/local/lib/python3.9/dist-packages/pandas/core/indexing.py", line 1751, in _setitem_with_indexer
    raise ValueError(
ValueError: cannot set a frame with no defined index and a scalar

Assay endpoint with aeid=2655 failed: cannot set a frame with no defined index and a scalar
Traceback (most recent call last):
  File "/home/bossh/pytcpl/src/pipeline/pipeline_main.py", line 43, in pipeline
    df = process(df, config, logger)
  File "/home/bossh/pytcpl/src/pipeline/pipeline_core.py", line 189, in process
    df_no_fit.loc[:, 'fit_params'] = None
  File "/usr/local/lib/python3.9/dist-packages/pandas/core/indexing.py", line 849, in __setitem__
    iloc._setitem_with_indexer(indexer, value, self.name)
  File "/usr/local/lib/python3.9/dist-packages/pandas/core/indexing.py", line 1751, in _setitem_with_indexer
    raise ValueError(
ValueError: cannot set a frame with no defined index and a scalar

Assay endpoint with aeid=2661 failed: cannot set a frame with no defined index and a scalar
Traceback (most recent call last):
  File "/home/bossh/pytcpl/src/pipeline/pipeline_main.py", line 43, in pipeline
    df = process(df, config, logger)
  File "/home/bossh/pytcpl/src/pipeline/pipeline_core.py", line 189, in process
    df_no_fit.loc[:, 'fit_params'] = None
  File "/usr/local/lib/python3.9/dist-packages/pandas/core/indexing.py", line 849, in __setitem__
    iloc._setitem_with_indexer(indexer, value, self.name)
  File "/usr/local/lib/python3.9/dist-packages/pandas/core/indexing.py", line 1751, in _setitem_with_indexer
    raise ValueError(
ValueError: cannot set a frame with no defined index and a scalar

Assay endpoint with aeid=2568 failed: cannot set a frame with no defined index and a scalar
Traceback (most recent call last):
  File "/home/bossh/pytcpl/src/pipeline/pipeline_main.py", line 43, in pipeline
    df = process(df, config, logger)
  File "/home/bossh/pytcpl/src/pipeline/pipeline_core.py", line 189, in process
    df_no_fit.loc[:, 'fit_params'] = None
  File "/usr/local/lib/python3.9/dist-packages/pandas/core/indexing.py", line 849, in __setitem__
    iloc._setitem_with_indexer(indexer, value, self.name)
  File "/usr/local/lib/python3.9/dist-packages/pandas/core/indexing.py", line 1751, in _setitem_with_indexer
    raise ValueError(
ValueError: cannot set a frame with no defined index and a scalar

Assay endpoint with aeid=2654 failed: cannot set a frame with no defined index and a scalar
Traceback (most recent call last):
  File "/home/bossh/pytcpl/src/pipeline/pipeline_main.py", line 43, in pipeline
    df = process(df, config, logger)
  File "/home/bossh/pytcpl/src/pipeline/pipeline_core.py", line 189, in process
    df_no_fit.loc[:, 'fit_params'] = None
  File "/usr/local/lib/python3.9/dist-packages/pandas/core/indexing.py", line 849, in __setitem__
    iloc._setitem_with_indexer(indexer, value, self.name)
  File "/usr/local/lib/python3.9/dist-packages/pandas/core/indexing.py", line 1751, in _setitem_with_indexer
    raise ValueError(
ValueError: cannot set a frame with no defined index and a scalar

Assay endpoint with aeid=2605 failed: cannot set a frame with no defined index and a scalar
Traceback (most recent call last):
  File "/home/bossh/pytcpl/src/pipeline/pipeline_main.py", line 43, in pipeline
    df = process(df, config, logger)
  File "/home/bossh/pytcpl/src/pipeline/pipeline_core.py", line 189, in process
    df_no_fit.loc[:, 'fit_params'] = None
  File "/usr/local/lib/python3.9/dist-packages/pandas/core/indexing.py", line 849, in __setitem__
    iloc._setitem_with_indexer(indexer, value, self.name)
  File "/usr/local/lib/python3.9/dist-packages/pandas/core/indexing.py", line 1751, in _setitem_with_indexer
    raise ValueError(
ValueError: cannot set a frame with no defined index and a scalar

Assay endpoint with aeid=2591 failed: cannot set a frame with no defined index and a scalar
Traceback (most recent call last):
  File "/home/bossh/pytcpl/src/pipeline/pipeline_main.py", line 43, in pipeline
    df = process(df, config, logger)
  File "/home/bossh/pytcpl/src/pipeline/pipeline_core.py", line 189, in process
    df_no_fit.loc[:, 'fit_params'] = None
  File "/usr/local/lib/python3.9/dist-packages/pandas/core/indexing.py", line 849, in __setitem__
    iloc._setitem_with_indexer(indexer, value, self.name)
  File "/usr/local/lib/python3.9/dist-packages/pandas/core/indexing.py", line 1751, in _setitem_with_indexer
    raise ValueError(
ValueError: cannot set a frame with no defined index and a scalar

Assay endpoint with aeid=2584 failed: cannot set a frame with no defined index and a scalar
Traceback (most recent call last):
  File "/home/bossh/pytcpl/src/pipeline/pipeline_main.py", line 43, in pipeline
    df = process(df, config, logger)
  File "/home/bossh/pytcpl/src/pipeline/pipeline_core.py", line 189, in process
    df_no_fit.loc[:, 'fit_params'] = None
  File "/usr/local/lib/python3.9/dist-packages/pandas/core/indexing.py", line 849, in __setitem__
    iloc._setitem_with_indexer(indexer, value, self.name)
  File "/usr/local/lib/python3.9/dist-packages/pandas/core/indexing.py", line 1751, in _setitem_with_indexer
    raise ValueError(
ValueError: cannot set a frame with no defined index and a scalar

Assay endpoint with aeid=2636 failed: cannot set a frame with no defined index and a scalar
Traceback (most recent call last):
  File "/home/bossh/pytcpl/src/pipeline/pipeline_main.py", line 43, in pipeline
    df = process(df, config, logger)
  File "/home/bossh/pytcpl/src/pipeline/pipeline_core.py", line 189, in process
    df_no_fit.loc[:, 'fit_params'] = None
  File "/usr/local/lib/python3.9/dist-packages/pandas/core/indexing.py", line 849, in __setitem__
    iloc._setitem_with_indexer(indexer, value, self.name)
  File "/usr/local/lib/python3.9/dist-packages/pandas/core/indexing.py", line 1751, in _setitem_with_indexer
    raise ValueError(
ValueError: cannot set a frame with no defined index and a scalar

Assay endpoint with aeid=2556 failed: cannot set a frame with no defined index and a scalar
Traceback (most recent call last):
  File "/home/bossh/pytcpl/src/pipeline/pipeline_main.py", line 43, in pipeline
    df = process(df, config, logger)
  File "/home/bossh/pytcpl/src/pipeline/pipeline_core.py", line 189, in process
    df_no_fit.loc[:, 'fit_params'] = None
  File "/usr/local/lib/python3.9/dist-packages/pandas/core/indexing.py", line 849, in __setitem__
    iloc._setitem_with_indexer(indexer, value, self.name)
  File "/usr/local/lib/python3.9/dist-packages/pandas/core/indexing.py", line 1751, in _setitem_with_indexer
    raise ValueError(
ValueError: cannot set a frame with no defined index and a scalar

Assay endpoint with aeid=2613 failed: cannot set a frame with no defined index and a scalar
Traceback (most recent call last):
  File "/home/bossh/pytcpl/src/pipeline/pipeline_main.py", line 43, in pipeline
    df = process(df, config, logger)
  File "/home/bossh/pytcpl/src/pipeline/pipeline_core.py", line 189, in process
    df_no_fit.loc[:, 'fit_params'] = None
  File "/usr/local/lib/python3.9/dist-packages/pandas/core/indexing.py", line 849, in __setitem__
    iloc._setitem_with_indexer(indexer, value, self.name)
  File "/usr/local/lib/python3.9/dist-packages/pandas/core/indexing.py", line 1751, in _setitem_with_indexer
    raise ValueError(
ValueError: cannot set a frame with no defined index and a scalar

Assay endpoint with aeid=2565 failed: cannot set a frame with no defined index and a scalar
Traceback (most recent call last):
  File "/home/bossh/pytcpl/src/pipeline/pipeline_main.py", line 43, in pipeline
    df = process(df, config, logger)
  File "/home/bossh/pytcpl/src/pipeline/pipeline_core.py", line 189, in process
    df_no_fit.loc[:, 'fit_params'] = None
  File "/usr/local/lib/python3.9/dist-packages/pandas/core/indexing.py", line 849, in __setitem__
    iloc._setitem_with_indexer(indexer, value, self.name)
  File "/usr/local/lib/python3.9/dist-packages/pandas/core/indexing.py", line 1751, in _setitem_with_indexer
    raise ValueError(
ValueError: cannot set a frame with no defined index and a scalar

