Assay endpoint with aeid=2555 failed: cannot set a frame with no defined index and a scalar
Traceback (most recent call last):
  File "/home/bossh/pytcpl/src/pipeline/pipeline_main.py", line 43, in pipeline
    df = process(df, config, logger)
  File "/home/bossh/pytcpl/src/pipeline/pipeline_core.py", line 189, in process
    df_no_fit.loc[:, 'fit_params'] = None
  File "/usr/local/lib/python3.9/dist-packages/pandas/core/indexing.py", line 849, in __setitem__
    iloc._setitem_with_indexer(indexer, value, self.name)
  File "/usr/local/lib/python3.9/dist-packages/pandas/core/indexing.py", line 1751, in _setitem_with_indexer
    raise ValueError(
ValueError: cannot set a frame with no defined index and a scalar

Assay endpoint with aeid=2553 failed: cannot set a frame with no defined index and a scalar
Traceback (most recent call last):
  File "/home/bossh/pytcpl/src/pipeline/pipeline_main.py", line 43, in pipeline
    df = process(df, config, logger)
  File "/home/bossh/pytcpl/src/pipeline/pipeline_core.py", line 189, in process
    df_no_fit.loc[:, 'fit_params'] = None
  File "/usr/local/lib/python3.9/dist-packages/pandas/core/indexing.py", line 849, in __setitem__
    iloc._setitem_with_indexer(indexer, value, self.name)
  File "/usr/local/lib/python3.9/dist-packages/pandas/core/indexing.py", line 1751, in _setitem_with_indexer
    raise ValueError(
ValueError: cannot set a frame with no defined index and a scalar

Assay endpoint with aeid=2693 failed: cannot set a frame with no defined index and a scalar
Traceback (most recent call last):
  File "/home/bossh/pytcpl/src/pipeline/pipeline_main.py", line 43, in pipeline
    df = process(df, config, logger)
  File "/home/bossh/pytcpl/src/pipeline/pipeline_core.py", line 189, in process
    df_no_fit.loc[:, 'fit_params'] = None
  File "/usr/local/lib/python3.9/dist-packages/pandas/core/indexing.py", line 849, in __setitem__
    iloc._setitem_with_indexer(indexer, value, self.name)
  File "/usr/local/lib/python3.9/dist-packages/pandas/core/indexing.py", line 1751, in _setitem_with_indexer
    raise ValueError(
ValueError: cannot set a frame with no defined index and a scalar

Assay endpoint with aeid=2696 failed: cannot set a frame with no defined index and a scalar
Traceback (most recent call last):
  File "/home/bossh/pytcpl/src/pipeline/pipeline_main.py", line 43, in pipeline
    df = process(df, config, logger)
  File "/home/bossh/pytcpl/src/pipeline/pipeline_core.py", line 189, in process
    df_no_fit.loc[:, 'fit_params'] = None
  File "/usr/local/lib/python3.9/dist-packages/pandas/core/indexing.py", line 849, in __setitem__
    iloc._setitem_with_indexer(indexer, value, self.name)
  File "/usr/local/lib/python3.9/dist-packages/pandas/core/indexing.py", line 1751, in _setitem_with_indexer
    raise ValueError(
ValueError: cannot set a frame with no defined index and a scalar

Assay endpoint with aeid=2680 failed: cannot set a frame with no defined index and a scalar
Traceback (most recent call last):
  File "/home/bossh/pytcpl/src/pipeline/pipeline_main.py", line 43, in pipeline
    df = process(df, config, logger)
  File "/home/bossh/pytcpl/src/pipeline/pipeline_core.py", line 189, in process
    df_no_fit.loc[:, 'fit_params'] = None
  File "/usr/local/lib/python3.9/dist-packages/pandas/core/indexing.py", line 849, in __setitem__
    iloc._setitem_with_indexer(indexer, value, self.name)
  File "/usr/local/lib/python3.9/dist-packages/pandas/core/indexing.py", line 1751, in _setitem_with_indexer
    raise ValueError(
ValueError: cannot set a frame with no defined index and a scalar

Assay endpoint with aeid=2631 failed: cannot set a frame with no defined index and a scalar
Traceback (most recent call last):
  File "/home/bossh/pytcpl/src/pipeline/pipeline_main.py", line 43, in pipeline
    df = process(df, config, logger)
  File "/home/bossh/pytcpl/src/pipeline/pipeline_core.py", line 189, in process
    df_no_fit.loc[:, 'fit_params'] = None
  File "/usr/local/lib/python3.9/dist-packages/pandas/core/indexing.py", line 849, in __setitem__
    iloc._setitem_with_indexer(indexer, value, self.name)
  File "/usr/local/lib/python3.9/dist-packages/pandas/core/indexing.py", line 1751, in _setitem_with_indexer
    raise ValueError(
ValueError: cannot set a frame with no defined index and a scalar

Assay endpoint with aeid=2611 failed: cannot set a frame with no defined index and a scalar
Traceback (most recent call last):
  File "/home/bossh/pytcpl/src/pipeline/pipeline_main.py", line 43, in pipeline
    df = process(df, config, logger)
  File "/home/bossh/pytcpl/src/pipeline/pipeline_core.py", line 189, in process
    df_no_fit.loc[:, 'fit_params'] = None
  File "/usr/local/lib/python3.9/dist-packages/pandas/core/indexing.py", line 849, in __setitem__
    iloc._setitem_with_indexer(indexer, value, self.name)
  File "/usr/local/lib/python3.9/dist-packages/pandas/core/indexing.py", line 1751, in _setitem_with_indexer
    raise ValueError(
ValueError: cannot set a frame with no defined index and a scalar

Assay endpoint with aeid=2644 failed: cannot set a frame with no defined index and a scalar
Traceback (most recent call last):
  File "/home/bossh/pytcpl/src/pipeline/pipeline_main.py", line 43, in pipeline
    df = process(df, config, logger)
  File "/home/bossh/pytcpl/src/pipeline/pipeline_core.py", line 189, in process
    df_no_fit.loc[:, 'fit_params'] = None
  File "/usr/local/lib/python3.9/dist-packages/pandas/core/indexing.py", line 849, in __setitem__
    iloc._setitem_with_indexer(indexer, value, self.name)
  File "/usr/local/lib/python3.9/dist-packages/pandas/core/indexing.py", line 1751, in _setitem_with_indexer
    raise ValueError(
ValueError: cannot set a frame with no defined index and a scalar

Assay endpoint with aeid=2582 failed: cannot set a frame with no defined index and a scalar
Traceback (most recent call last):
  File "/home/bossh/pytcpl/src/pipeline/pipeline_main.py", line 43, in pipeline
    df = process(df, config, logger)
  File "/home/bossh/pytcpl/src/pipeline/pipeline_core.py", line 189, in process
    df_no_fit.loc[:, 'fit_params'] = None
  File "/usr/local/lib/python3.9/dist-packages/pandas/core/indexing.py", line 849, in __setitem__
    iloc._setitem_with_indexer(indexer, value, self.name)
  File "/usr/local/lib/python3.9/dist-packages/pandas/core/indexing.py", line 1751, in _setitem_with_indexer
    raise ValueError(
ValueError: cannot set a frame with no defined index and a scalar

Assay endpoint with aeid=2672 failed: cannot set a frame with no defined index and a scalar
Traceback (most recent call last):
  File "/home/bossh/pytcpl/src/pipeline/pipeline_main.py", line 43, in pipeline
    df = process(df, config, logger)
  File "/home/bossh/pytcpl/src/pipeline/pipeline_core.py", line 189, in process
    df_no_fit.loc[:, 'fit_params'] = None
  File "/usr/local/lib/python3.9/dist-packages/pandas/core/indexing.py", line 849, in __setitem__
    iloc._setitem_with_indexer(indexer, value, self.name)
  File "/usr/local/lib/python3.9/dist-packages/pandas/core/indexing.py", line 1751, in _setitem_with_indexer
    raise ValueError(
ValueError: cannot set a frame with no defined index and a scalar

Assay endpoint with aeid=2566 failed: cannot set a frame with no defined index and a scalar
Traceback (most recent call last):
  File "/home/bossh/pytcpl/src/pipeline/pipeline_main.py", line 43, in pipeline
    df = process(df, config, logger)
  File "/home/bossh/pytcpl/src/pipeline/pipeline_core.py", line 189, in process
    df_no_fit.loc[:, 'fit_params'] = None
  File "/usr/local/lib/python3.9/dist-packages/pandas/core/indexing.py", line 849, in __setitem__
    iloc._setitem_with_indexer(indexer, value, self.name)
  File "/usr/local/lib/python3.9/dist-packages/pandas/core/indexing.py", line 1751, in _setitem_with_indexer
    raise ValueError(
ValueError: cannot set a frame with no defined index and a scalar

Assay endpoint with aeid=2571 failed: cannot set a frame with no defined index and a scalar
Traceback (most recent call last):
  File "/home/bossh/pytcpl/src/pipeline/pipeline_main.py", line 43, in pipeline
    df = process(df, config, logger)
  File "/home/bossh/pytcpl/src/pipeline/pipeline_core.py", line 189, in process
    df_no_fit.loc[:, 'fit_params'] = None
  File "/usr/local/lib/python3.9/dist-packages/pandas/core/indexing.py", line 849, in __setitem__
    iloc._setitem_with_indexer(indexer, value, self.name)
  File "/usr/local/lib/python3.9/dist-packages/pandas/core/indexing.py", line 1751, in _setitem_with_indexer
    raise ValueError(
ValueError: cannot set a frame with no defined index and a scalar

Assay endpoint with aeid=2569 failed: cannot set a frame with no defined index and a scalar
Traceback (most recent call last):
  File "/home/bossh/pytcpl/src/pipeline/pipeline_main.py", line 43, in pipeline
    df = process(df, config, logger)
  File "/home/bossh/pytcpl/src/pipeline/pipeline_core.py", line 189, in process
    df_no_fit.loc[:, 'fit_params'] = None
  File "/usr/local/lib/python3.9/dist-packages/pandas/core/indexing.py", line 849, in __setitem__
    iloc._setitem_with_indexer(indexer, value, self.name)
  File "/usr/local/lib/python3.9/dist-packages/pandas/core/indexing.py", line 1751, in _setitem_with_indexer
    raise ValueError(
ValueError: cannot set a frame with no defined index and a scalar

Assay endpoint with aeid=2663 failed: cannot set a frame with no defined index and a scalar
Traceback (most recent call last):
  File "/home/bossh/pytcpl/src/pipeline/pipeline_main.py", line 43, in pipeline
    df = process(df, config, logger)
  File "/home/bossh/pytcpl/src/pipeline/pipeline_core.py", line 189, in process
    df_no_fit.loc[:, 'fit_params'] = None
  File "/usr/local/lib/python3.9/dist-packages/pandas/core/indexing.py", line 849, in __setitem__
    iloc._setitem_with_indexer(indexer, value, self.name)
  File "/usr/local/lib/python3.9/dist-packages/pandas/core/indexing.py", line 1751, in _setitem_with_indexer
    raise ValueError(
ValueError: cannot set a frame with no defined index and a scalar

Assay endpoint with aeid=2552 failed: cannot set a frame with no defined index and a scalar
Traceback (most recent call last):
  File "/home/bossh/pytcpl/src/pipeline/pipeline_main.py", line 43, in pipeline
    df = process(df, config, logger)
  File "/home/bossh/pytcpl/src/pipeline/pipeline_core.py", line 189, in process
    df_no_fit.loc[:, 'fit_params'] = None
  File "/usr/local/lib/python3.9/dist-packages/pandas/core/indexing.py", line 849, in __setitem__
    iloc._setitem_with_indexer(indexer, value, self.name)
  File "/usr/local/lib/python3.9/dist-packages/pandas/core/indexing.py", line 1751, in _setitem_with_indexer
    raise ValueError(
ValueError: cannot set a frame with no defined index and a scalar

Assay endpoint with aeid=2633 failed: cannot set a frame with no defined index and a scalar
Traceback (most recent call last):
  File "/home/bossh/pytcpl/src/pipeline/pipeline_main.py", line 43, in pipeline
    df = process(df, config, logger)
  File "/home/bossh/pytcpl/src/pipeline/pipeline_core.py", line 189, in process
    df_no_fit.loc[:, 'fit_params'] = None
  File "/usr/local/lib/python3.9/dist-packages/pandas/core/indexing.py", line 849, in __setitem__
    iloc._setitem_with_indexer(indexer, value, self.name)
  File "/usr/local/lib/python3.9/dist-packages/pandas/core/indexing.py", line 1751, in _setitem_with_indexer
    raise ValueError(
ValueError: cannot set a frame with no defined index and a scalar

Assay endpoint with aeid=2688 failed: cannot set a frame with no defined index and a scalar
Traceback (most recent call last):
  File "/home/bossh/pytcpl/src/pipeline/pipeline_main.py", line 43, in pipeline
    df = process(df, config, logger)
  File "/home/bossh/pytcpl/src/pipeline/pipeline_core.py", line 189, in process
    df_no_fit.loc[:, 'fit_params'] = None
  File "/usr/local/lib/python3.9/dist-packages/pandas/core/indexing.py", line 849, in __setitem__
    iloc._setitem_with_indexer(indexer, value, self.name)
  File "/usr/local/lib/python3.9/dist-packages/pandas/core/indexing.py", line 1751, in _setitem_with_indexer
    raise ValueError(
ValueError: cannot set a frame with no defined index and a scalar

Assay endpoint with aeid=2614 failed: cannot set a frame with no defined index and a scalar
Traceback (most recent call last):
  File "/home/bossh/pytcpl/src/pipeline/pipeline_main.py", line 43, in pipeline
    df = process(df, config, logger)
  File "/home/bossh/pytcpl/src/pipeline/pipeline_core.py", line 189, in process
    df_no_fit.loc[:, 'fit_params'] = None
  File "/usr/local/lib/python3.9/dist-packages/pandas/core/indexing.py", line 849, in __setitem__
    iloc._setitem_with_indexer(indexer, value, self.name)
  File "/usr/local/lib/python3.9/dist-packages/pandas/core/indexing.py", line 1751, in _setitem_with_indexer
    raise ValueError(
ValueError: cannot set a frame with no defined index and a scalar

Assay endpoint with aeid=2607 failed: cannot set a frame with no defined index and a scalar
Traceback (most recent call last):
  File "/home/bossh/pytcpl/src/pipeline/pipeline_main.py", line 43, in pipeline
    df = process(df, config, logger)
  File "/home/bossh/pytcpl/src/pipeline/pipeline_core.py", line 189, in process
    df_no_fit.loc[:, 'fit_params'] = None
  File "/usr/local/lib/python3.9/dist-packages/pandas/core/indexing.py", line 849, in __setitem__
    iloc._setitem_with_indexer(indexer, value, self.name)
  File "/usr/local/lib/python3.9/dist-packages/pandas/core/indexing.py", line 1751, in _setitem_with_indexer
    raise ValueError(
ValueError: cannot set a frame with no defined index and a scalar

Assay endpoint with aeid=2635 failed: cannot set a frame with no defined index and a scalar
Traceback (most recent call last):
  File "/home/bossh/pytcpl/src/pipeline/pipeline_main.py", line 43, in pipeline
    df = process(df, config, logger)
  File "/home/bossh/pytcpl/src/pipeline/pipeline_core.py", line 189, in process
    df_no_fit.loc[:, 'fit_params'] = None
  File "/usr/local/lib/python3.9/dist-packages/pandas/core/indexing.py", line 849, in __setitem__
    iloc._setitem_with_indexer(indexer, value, self.name)
  File "/usr/local/lib/python3.9/dist-packages/pandas/core/indexing.py", line 1751, in _setitem_with_indexer
    raise ValueError(
ValueError: cannot set a frame with no defined index and a scalar

Assay endpoint with aeid=2646 failed: cannot set a frame with no defined index and a scalar
Traceback (most recent call last):
  File "/home/bossh/pytcpl/src/pipeline/pipeline_main.py", line 43, in pipeline
    df = process(df, config, logger)
  File "/home/bossh/pytcpl/src/pipeline/pipeline_core.py", line 189, in process
    df_no_fit.loc[:, 'fit_params'] = None
  File "/usr/local/lib/python3.9/dist-packages/pandas/core/indexing.py", line 849, in __setitem__
    iloc._setitem_with_indexer(indexer, value, self.name)
  File "/usr/local/lib/python3.9/dist-packages/pandas/core/indexing.py", line 1751, in _setitem_with_indexer
    raise ValueError(
ValueError: cannot set a frame with no defined index and a scalar

Assay endpoint with aeid=2657 failed: cannot set a frame with no defined index and a scalar
Traceback (most recent call last):
  File "/home/bossh/pytcpl/src/pipeline/pipeline_main.py", line 43, in pipeline
    df = process(df, config, logger)
  File "/home/bossh/pytcpl/src/pipeline/pipeline_core.py", line 189, in process
    df_no_fit.loc[:, 'fit_params'] = None
  File "/usr/local/lib/python3.9/dist-packages/pandas/core/indexing.py", line 849, in __setitem__
    iloc._setitem_with_indexer(indexer, value, self.name)
  File "/usr/local/lib/python3.9/dist-packages/pandas/core/indexing.py", line 1751, in _setitem_with_indexer
    raise ValueError(
ValueError: cannot set a frame with no defined index and a scalar

Assay endpoint with aeid=2677 failed: cannot set a frame with no defined index and a scalar
Traceback (most recent call last):
  File "/home/bossh/pytcpl/src/pipeline/pipeline_main.py", line 43, in pipeline
    df = process(df, config, logger)
  File "/home/bossh/pytcpl/src/pipeline/pipeline_core.py", line 189, in process
    df_no_fit.loc[:, 'fit_params'] = None
  File "/usr/local/lib/python3.9/dist-packages/pandas/core/indexing.py", line 849, in __setitem__
    iloc._setitem_with_indexer(indexer, value, self.name)
  File "/usr/local/lib/python3.9/dist-packages/pandas/core/indexing.py", line 1751, in _setitem_with_indexer
    raise ValueError(
ValueError: cannot set a frame with no defined index and a scalar

